File: Environnement_programmation/Cours python/TD-TraceCourbe/ResultatsTraction/Essais/data17.txt
# Time [s]	Stress [Pa]	Strain
0.000000e+00	5.470072e+05	9.471331e-05
2.400000e-01	8.058608e+06	5.498501e-04
4.800000e-01	1.595390e+07	1.189462e-03
7.200000e-01	2.551024e+07	1.961372e-03
9.600000e-01	2.988131e+07	2.638469e-03
1.200000e+00	3.033657e+07	3.165967e-03
1.440000e+00	3.149433e+07	3.762567e-03
1.680000e+00	3.266217e+07	4.576629e-03
1.920000e+00	3.324387e+07	5.275806e-03
2.160000e+00	3.497632e+07	5.808083e-03
# Creation : Jeudi 3 novembre 2011, 23:09:57