File: Environnement_programmation/Cours python/TD-TraceCourbe/Corrige/TD-TraceCourbe_corrige/ResultatsTraction/Essais/data21.txt
# Time [s]	Stress [Pa]	Strain
0.000000e+00	4.677798e+05	8.241408e-06
2.400000e-01	8.733393e+06	6.240761e-04
4.800000e-01	1.746571e+07	1.344399e-03
7.200000e-01	2.733509e+07	2.032330e-03
9.600000e-01	3.239561e+07	2.519629e-03
1.200000e+00	3.277683e+07	3.219942e-03
1.440000e+00	3.317864e+07	3.843757e-03
1.680000e+00	3.350640e+07	4.523549e-03
1.920000e+00	3.512248e+07	5.106697e-03
2.160000e+00	3.568555e+07	5.970152e-03
# Creation : Jeudi 3 novembre 2011, 23:09:57