File: Environnement_programmation/Cours python/TD-TraceCourbe/Corrige/TD-TraceCourbe_corrige/ResultatsTraction/Essais/data10.txt
# Time [s]	Stress [Pa]	Strain
0.000000e+00	4.905994e+05	4.976974e-05
2.500000e-01	7.611425e+06	6.204072e-04
5.000000e-01	1.627979e+07	1.362973e-03
7.500000e-01	2.468474e+07	1.929268e-03
1.000000e+00	3.160449e+07	2.521794e-03
1.250000e+00	3.375019e+07	3.182723e-03
1.500000e+00	3.465382e+07	3.816619e-03
1.750000e+00	3.481755e+07	4.413621e-03
2.000000e+00	3.647131e+07	4.987330e-03
2.250000e+00	3.681045e+07	5.682557e-03
# Creation : Jeudi 3 novembre 2011, 23:09:56