File: Environnement_programmation/Cours python/TD-TraceCourbe/Corrige/TD-TraceCourbe_corrige/ResultatsTraction/Essais/data08.txt
# Time [s]	Stress [Pa]	Strain
0.000000e+00	6.915352e+05	1.177483e-04
2.500000e-01	9.860247e+06	6.744026e-04
5.000000e-01	2.016242e+07	1.234916e-03
7.500000e-01	2.994049e+07	1.859270e-03
1.000000e+00	3.369651e+07	2.484350e-03
1.250000e+00	3.458178e+07	3.252419e-03
1.500000e+00	3.441331e+07	3.947695e-03
1.750000e+00	3.498547e+07	4.549536e-03
2.000000e+00	3.510909e+07	5.035067e-03
2.250000e+00	3.504000e+07	5.785022e-03
# Creation : Jeudi 3 novembre 2011, 23:09:56